Workbook

Sheet Groupe business-plan
B2: LES TABLEAUX DE L'ETUDE TECHNIQUE & FINANCIERE
B5: Raison Sociale :
B9: BUSINESS PLAN: ANNEE ACADEMIQUE
B11: PROMOTEURS QUI ONT TRAVAILLE | I11: ENSEIGNANT ENCADREUR:
B13: Prénoms | C13: Nom | D13: CLASSE: | I13: M. ou Mme ou Mlle
B14: Habibatou | C14: DRAME | D14: SI
B15: Arona | C15: FALL | D15: SR
B16: Awa | C16: NDIAYE | D16: SI
B17: Sokhna Magné | C17: MBOUP | D17: SI
B20: Moussa B | C20: DAFF | D20: SR
B21: Tamsir | C21: GUEYE | D21: SI
B23: PROMOTEURS QUI N'ONT PAS TRAVAILLE

Sheet Immobilisations
B3: CHARGES IMMOBILISEES
C6: FRAIS D'ETABLISSEMENT
C8: Nature des frais | D8: Montant
C9: Droit d'enregistrement | D9: 10000
C10: Honoraires du Notaire | D10: 15000
C11: Dossier de d'exercer | D11: 12000
C12: Timbres fiscaux | D12: 0
C13: Timbre NINEA | D13: 0
C14: Frais d'ouverture de compte | D14: 27000
C15: Frais d'étude | D15: 50000
C16: Frais d'immatriculation | D16: 0
C17: publication au journal officiel | D17: 0
C19: TOTAL | D19: =SUM(D15:D18)+SUM(D9:D14) -> 114000
B23: IMMOBILISATIONS INCORPORELLES
C26: IMMOBILISATIONS INCORPORELLES
C28: Nature des frais | D28: Montant
C29: Frais de Recherche et Développement | D29: 150000
C30: Brevet, Licence, Concession | D30: 30000
C31: Logiciels | D31: 650000
C32: Marque | D32: 100000
C33: Fonds commercial
C34: Autres | D34: 250000
C36: TOTAL | D36: =SUM(D29:D34) -> 1180000
B41: IMMOBILISATIONS CORPORELLES
C44: EQUIPEMENTS D'EXPLOITATION
C46: Nature des Equipements | D46: Quantité | E46: Prix unitaire | F46: Montant
C48: boite de gants nitriles | D48: 2 | E48: 11200 | F48: =E48*D48 -> 22400
C49: Masque de protection | D49: 6 | E49: 22300 | F49: =E49*D49 -> 133800
C50: Balance electrique | D50: 1 | E50: 9300 | F50: =E50*D50 -> 9300
C51: Fleurs séchées | D51: 1 | E51: 10550 | F51: =E51*D51 -> 10550
C52: Ponpon | D52: 10 | E52: 3050 | F52: =E52*D52 -> 30500
C53: Pack Autocollant | D53: 10 | E53: 3800 | F53: =E53*D53 -> 38000
C54: Moule | D54: 15 | E54: 5000 | F54: =E54*D54 -> 75000
C55: Pot de rangement | D55: 5 | E55: 2640 | F55: =E55*D55 -> 13200
C56: Paillette | D56: 6 | E56: 6560 | F56: =E56*D56 -> 39360
C57: Encre à alcool | D57: 6 | E57: 13200 | F57: =E57*D57 -> 79200
C58: Paquet de Colorant | D58: 5 | E58: 11250 | F58: =E58*D58 -> 56250
C59: Poudre de mica | D59: 6 | E59: 14550 | F59: =E59*D59 -> 87300
C60: Feuille d'or | D60: 50 | E60: 5950 | F60: =E60*D60 -> 297500
C62: TOTAL | F62: =SUM(F47:F60) -> 892360
...

Sheet amortis
A3: Immobilisations | B3: Montant | C3: DUP | D3: 1ère année | F3: 2ème année | H3: 3ème année | J3: 4ème année | L3: 5ème
D4: Amortissement | E4: V C N | F4: Amortissement | G4: V C N | H4: Amortissement | I4: V C N | J4: Amortissement | K4: V C N | L4: Amortissement | M4: V C N
A5: Frais d'établissement | B5: =Immobilisations!D19 -> 114000 | C5: 5 | D5: =B5/C5 -> 22800 | E5: =B5-D5 -> 91200 | F5: =D5 -> 22800 | G5: =E5-F5 -> 68400 | H5: =D5 -> 22800 | I5: =G5-H5 -> 45600 | J5: =D5 -> 22800 | K5: =I5-J5 -> 22800 | L5: =D5 -> 22800 | M5: =K5-L5 -> 0
A7: Immobilisations incorporelles | B7: =Immobilisations!D36 -> 1180000 | C7: 5 | D7: =B7/C7 -> 236000 | E7: =B7-D7 -> 944000 | F7: =D7 -> 236000 | G7: =E7-F7 -> 708000 | H7: =D7 -> 236000 | I7: =G7-H7 -> 472000 | J7: =D7 -> 236000 | K7: =I7-J7 -> 236000 | L7: =D7 -> 236000 | M7: =K7-L7 -> 0
A9: =Immobilisations!C48 -> boite de gants nitriles | B9: =Immobilisations!F48 -> 22400 | C9: 10 | D9: =B9/C9 -> 2240 | E9: =B9-D9 -> 20160 | F9: =D9 -> 2240 | G9: =E9-F9 -> 17920 | H9: =D9 -> 2240 | I9: =G9-H9 -> 15680 | J9: =D9 -> 2240 | K9: =I9-J9 -> 13440 | L9: =D9 -> 2240 | M9: =K9-L9 -> 11200
A10: =Immobilisations!C49 -> Masque de protection | B10: =Immobilisations!F49 -> 133800 | C10: 10 | D10: =B10/C10 -> 13380 | E10: =B10-D10 -> 120420 | F10: =D10 -> 13380 | G10: =E10-F10 -> 107040 | H10: =D10 -> 13380 | I10: =G10-H10 -> 93660 | J10: =D10 -> 13380 | K10: =I10-J10 -> 80280 | L10: =D10 -> 13380 | M10: =K10-L10 -> 66900
A11: =Immobilisations!C50 -> Balance electrique | B11: =Immobilisations!F50 -> 9300 | C11: 5 | D11: =B11/C11 -> 1860 | E11: =B11-D11 -> 7440 | F11: =D11 -> 1860 | G11: =E11-F11 -> 5580 | H11: =D11 -> 1860 | I11: =G11-H11 -> 3720 | J11: =D11 -> 1860 | K11: =I11-J11 -> 1860 | L11: =D11 -> 1860 | M11: =K11-L11 -> 0
A12: =Immobilisations!C58 -> Paquet de Colorant | B12: =Immobilisations!F58 -> 56250 | C12: 1 | D12: =B12/C12 -> 56250 | E12: =B12-D12 -> 0 | F12: =D12 -> 56250 | G12: =E12-F12 -> -56250 | H12: =D12 -> 56250 | I12: =G12-H12 -> -112500 | J12: =D12 -> 56250 | K12: =I12-J12 -> -168750 | L12: =D12 -> 56250 | M12: =K12-L12 -> -225000
A13: =Immobilisations!C59 -> Poudre de mica | B13: =Immobilisations!F59 -> 87300 | C13: 1 | D13: =B13/C13 -> 87300 | E13: =B13-D13 -> 0 | F13: =D13 -> 87300 | G13: =E13-F13 -> -87300 | H13: =D13 -> 87300 | I13: =G13-H13 -> -174600 | J13: =D13 -> 87300 | K13: =I13-J13 -> -261900 | L13: =D13 -> 87300 | M13: =K13-L13 -> -349200
A14: =Immobilisations!C60 -> Feuille d'or | B14: =Immobilisations!F60 -> 297500 | C14: 1 | D14: =B14/C14 -> 297500 | E14: =B14-D14 -> 0 | F14: =D14 -> 297500 | G14: =E14-F14 -> -297500 | H14: =D14 -> 297500 | I14: =G14-H14 -> -595000 | J14: =D14 -> 297500 | K14: =I14-J14 -> -892500 | L14: =D14 -> 297500 | M14: =K14-L14 -> -1190000
A15: =Immobilisations!C68 -> Cricut maker 3 | B15: =Immobilisations!F68 -> 650000 | C15: 1 | D15: =B15/C15 -> 650000 | E15: =B15-D15 -> 0 | F15: =D15 -> 650000 | G15: =E15-F15 -> -650000 | H15: =D15 -> 650000 | I15: =G15-H15 -> -1300000 | J15: =D15 -> 650000 | K15: =I15-J15 -> -1950000 | L15: =D15 -> 650000 | M15: =K15-L15 -> -2600000
A16: =Immobilisations!C69 -> Table | B16: =Immobilisations!F69 -> 15000 | C16: 10 | D16: =B16/C16 -> 1500 | E16: =B16-D16 -> 13500 | F16: =D16 -> 1500 | G16: =E16-F16 -> 12000 | H16: =D16 -> 1500 | I16: =G16-H16 -> 10500 | J16: =D16 -> 1500 | K16: =I16-J16 -> 9000 | L16: =D16 -> 1500 | M16: =K16-L16 -> 7500
A17: =Immobilisations!C70 -> Ordinateur de bureau | B17: =Immobilisations!F70 -> 100000 | C17: 10 | D17: =B17/C17 -> 10000 | E17: =B17-D17 -> 90000 | F17: =D17 -> 10000 | G17: =E17-F17 -> 80000 | H17: =D17 -> 10000 | I17: =G17-H17 -> 70000 | J17: =D17 -> 10000 | K17: =I17-J17 -> 60000 | L17: =D17 -> 10000 | M17: =K17-L17 -> 50000
A18: =Immobilisations!C71 -> Imprimante | B18: =Immobilisations!F71 -> 65000 | C18: 10 | D18: =B18/C18 -> 6500 | E18: =B18-D18 -> 58500 | F18: =D18 -> 6500 | G18: =E18-F18 -> 52000 | H18: =D18 -> 6500 | I18: =G18-H18 -> 45500 | J18: =D18 -> 6500 | K18: =I18-J18 -> 39000 | L18: =D18 -> 6500 | M18: =K18-L18 -> 32500
A19: =Immobilisations!C72 -> Chaise | B19: =Immobilisations!F72 -> 30000 | C19: 5 | D19: =B19/C19 -> 6000 | E19: =B19-D19 -> 24000 | F19: =D19 -> 6000 | G19: =E19-F19 -> 18000 | H19: =D19 -> 6000 | I19: =G19-H19 -> 12000 | J19: =D19 -> 6000 | K19: =I19-J19 -> 6000 | L19: =D19 -> 6000 | M19: =K19-L19 -> 0
A20: =Immobilisations!C73 -> Autres Matériels et Mobiliers de bureau | B20: =Immobilisations!F73 -> 250000 | C20: 5 | D20: =B20/C20 -> 50000 | E20: =B20-D20 -> 200000 | F20: =D20 -> 50000 | G20: =E20-F20 -> 150000 | H20: =D20 -> 50000 | I20: =G20-H20 -> 100000 | J20: =D20 -> 50000 | K20: =I20-J20 -> 50000 | L20: =D20 -> 50000 | M20: =K20-L20 -> 0
A22: Installations, Travaux et Agencements | B22: =Immobilisations!F87 -> 190000 | C22: 5 | D22: =B22/C22 -> 38000 | E22: =B22-D22 -> 152000 | F22: =D22 -> 38000 | G22: =E22-F22 -> 114000 | H22: =D22 -> 38000 | I22: =G22-H22 -> 76000 | J22: =D22 -> 38000 | K22: =I22-J22 -> 38000 | L22: =D22 -> 38000 | M22: =K22-L22 -> 0
A24: TOTAL | B24: =SUM(B5:B23) -> 3200550 | D24: =SUM(D5:D23) -> 1479330 | F24: =D24 -> 1479330 | H24: =SUM(H5:H23) -> 1479330 | J24: =SUM(J5:J23) -> 1479330 | L24: =SUM(L5:L23) -> 1479330

Sheet Ressources Humaines
C6: Poste | D6: Nombre requis | E6: Profil ou niveau | F6: Salaire mensuel brut | G6: Total salaire mensuel brut | H6: Charges Sociales
C8: Assitant | D8: 1 | F8: 50000 | G8: =D8*F8 -> 50000 | H8: =G8*D25 -> 5300
C9: Community Manager | D9: 1 | F9: 75000 | G9: =D9*F9 -> 75000 | H9: =G9*D25 -> 7950
C10: Agent comptable | D10: 1 | F10: 100000 | G10: =F10*D10 -> 100000 | H10: =G10*D25 -> 10600
C11: Caissier | D11: 0 | F11: 55000 | G11: 55000 | H11: =G11*D25 -> 5830
C12: Livreur | D12: 1 | F12: 60000 | G12: =D12*F12 -> 60000 | H12: =G12*D25 -> 6360
C14: Total masse salariale mensuelle | G14: =SUM(G8:G13) -> 340000 | H14: =SUM(H8:H13) -> 36040
C15: Total masse salariale annuelle | G15: =PRODUCT(G14,12) -> 4080000 | H15: =PRODUCT(H14,12) -> 432480
C19: CHARGES SOCIALES
C20: Nature | D20: Barême
C21: CFCE | D21: 0.03
C22: IPRESS | D22: 0.056
C23: IPM | D23: 0.01
C24: CSS | D24: 0.01
C25: Total Charges | D25: =SUM(D21:D24) -> 0.106

Sheet Charges dexploitation
C4: Charges d'exploitation prévisionnelles | D4: Mensuelles | E4: Trimestrielles | F4: Semestrielles | G4: Annuelles
C6: Achats de marchandises | D6: 0
C7: Achats de matières premières et fournitures liées | D7: 892330 | F7: =D7*6 -> 5353980 | G7: =F7*2 -> 10707960
C8: Achats de consommables | D8: 0 | F8: =D8*6 -> 0 | G8: =F8*2 -> 0
C9: Achats de combustibles | D9: 0 | F9: =D9*6 -> 0 | G9: =F9*2 -> 0
C10: Achats de produits d'entretien | D10: 70000 | F10: =D10*6 -> 420000 | G10: =F10*2 -> 840000
C11: Achats de fournitures de bureau | D11: 1110000 | F11: =D11*6 -> 6660000 | G11: =F11*2 -> 13320000
C12: Eau (en terme de facture à payer) | D12: 2000 | F12: =D12*6 -> 12000 | G12: =F12*2 -> 24000
C13: Electricité (en terme de facture à payer) | D13: 20000 | F13: =D13*6 -> 120000 | G13: =F13*2 -> 240000
C14: Achats de petits matériels et outillages | D14: 0 | F14: =D14*6 -> 0 | G14: =F14*2 -> 0
C15: Etudes et prestations de service | D15: 0 | F15: =D15*6 -> 0 | G15: =F15*2 -> 0
C16: Achats d'emballages | D16: 50000 | F16: =D16*6 -> 300000 | G16: =F16*2 -> 600000
C17: Frais de transport | D17: 100000 | F17: =D17*6 -> 600000 | G17: =F17*2 -> 1200000
C18: Sous-traitance | D18: 60000 | F18: =D18*6 -> 360000 | G18: =F18*2 -> 720000
... C27: Charges provisionnées d'exploitation | D27: 0 | F27: =D27*6 -> 0 | G27: =F27*2 -> 0
C28: Salaires bruts et autres rémunérations | D28: ='Ressources Humaines'!G14 -> 340000 | F28: =D28*6 -> 2040000 | G28: ='Ressources Humaines'!G15 -> 4080000
C29: Charges sociales | D29: ='Ressources Humaines'!H14 -> 36040 | F29: =D29*6 -> 216240 | G29: ='Ressources Humaines'!H15 -> 432480
C30: Frais financiers | D30: 0 | E30: =emprunt!D11+emprunt!D12+emprunt!D13 -> 1050000 | F30: =SUM(emprunt!D11:D16) -> 1050000 | G30: =SUM(emprunt!D11:D22) -> 1050000
C31: Autres charges d'exploitation | D31: 0 | F31: =D31*6 -> 0 | G31: =F31*2 -> 0
G32: =F32*2 -> 0
C33: Total | D33: =SUM(D6:D32) -> 3555370 | E33: =SUM(E6:E32) -> 1050000 | F33: =SUM(F6:F32) -> 22382220 | G33: =SUM(G6:G32) -> 43714440

Sheet Coût du prjet
B3: COÛT DU PROJET
B6: Libellés | C6: Montant
B8: Charges immobilisées | C8: =C9 -> 114000
B9: Frais d'établissement | C9: =Immobilisations!D19 -> 114000
B10: Immobilisations incorporelles | C10: 830000
B11: Brevets | C11: 3000000
B12: Logiciels | C12: 200000
B13: Marques | C13: 500000
B14: Immobilisations corporelles | C14: =C15+C16+C17 -> 3112360
B15: Equipements d'exploitation | C15: =Immobilisations!F62 -> 892360
B16: Matériel et mobilier de bureau | C16: =Immobilisations!F75 -> 1110000
B17: Aménagements, travaux, installations,… | C17: =Immobilisations!F75 -> 1110000
B18: Immobilisations financières | C18: =C19 -> 182000
B19: Dépôts et Cautionnements | C19: =Immobilisations!D104 -> 182000
B20: ='Dotation en FR'!B37 -> Dotation trimestrielle ou semestrielle en Fonds de Roulement | C20: 300000
B22: Total Coût du projet | C22: =SUM(C8:C20) -> 11646720

Sheet Dotation en FR
B2: DOTATION EN FONDS DE ROULEMENT
B4: Eléments du Besoin de Financement d'Exploitation | C4: 1ère année | D4: 2ème année | E4: 3ème année
B5: Niveau d'activité | C5: 1 | D5: 1 | E5: 1
B7: ='Charges dexploitation'!C6 -> Achats de marchandises | C7: =$C$5*D7 -> 0 | D7: ='Charges dexploitation'!G6 | E7: =D7*$E$5 -> 0
B8: ='Charges dexploitation'!C7 -> Achats de matières premières et fournitures liées | C8: =$C$5*D8 -> 10707960 | D8: ='Charges dexploitation'!G7 -> 10707960 | E8: =D8*$E$5 -> 10707960
B9: ='Charges dexploitation'!C8 -> Achats de consommables | C9: =$C$5*D9 -> 0 | D9: ='Charges dexploitation'!G8 -> 0 | E9: =D9*$E$5 -> 0
B10: ='Charges dexploitation'!C9 -> Achats de combustibles | C10: =$C$5*D10 -> 0 | D10: ='Charges dexploitation'!G9 -> 0 | E10: =D10*$E$5 -> 0
B11: ='Charges dexploitation'!C10 -> Achats de produits d'entretien | C11: =$C$5*D11 -> 840000 | D11: ='Charges dexploitation'!G10 -> 840000 | E11: =D11*$E$5 -> 840000
B12: ='Charges dexploitation'!C11 -> Achats de fournitures de bureau | C12: =$C$5*D12 -> 13320000 | D12: ='Charges dexploitation'!G11 -> 13320000 | E12: =D12*$E$5 -> 13320000
B13: ='Charges dexploitation'!C12 -> Eau (en terme de facture à payer) | C13: =$C$5*D13 -> 24000 | D13: ='Charges dexploitation'!G12 -> 24000 | E13: =D13*$E$5 -> 24000
B14: ='Charges dexploitation'!C13 -> Electricité (en terme de facture à payer) | C14: =$C$5*D14 -> 240000 | D14: ='Charges dexploitation'!G13 -> 240000 | E14: =D14*$E$5 -> 240000
B15: ='Charges dexploitation'!C14 -> Achats de petits matériels et outillages | C15: =$C$5*D15 -> 0 | D15: ='Charges dexploitation'!G14 -> 0 | E15: =D15*$E$5 -> 0
B16: ='Charges dexploitation'!C15 -> Etudes et prestations de service | C16: =$C$5*D16 -> 0 | D16: ='Charges dexploitation'!G15 -> 0 | E16: =D16*$E$5 -> 0
B17: ='Charges dexploitation'!C16 -> Achats d'emballages | C17: =$C$5*D17 -> 600000 | D17: ='Charges dexploitation'!G16 -> 600000 | E17: =D17*$E$5 -> 600000
B18: ='Charges dexploitation'!C17 -> Frais de transport | C18: =$C$5*D18 -> 1200000 | D18: ='Charges dexploitation'!G17 -> 1200000 | E18: =D18*$E$5 -> 1200000
... B30: ='Charges dexploitation'!C29 -> Charges sociales | C30: =$C$5*D30 -> 432480 | D30: ='Charges dexploitation'!G29 -> 432480 | E30: =D30*$E$5 -> 432480
B31: ='Charges dexploitation'!C30 -> Frais financiers | C31: =SUM(emprunt!D11:D22)+SUM(emprunt!E11:E22) -> 1123500 | D31: =SUM(emprunt!D23:D34)+SUM(emprunt!E23:E34) -> 0 | E31: =SUM(emprunt!D35:D46)+SUM(emprunt!E35:E46) -> 0
B32: ='Charges dexploitation'!C31 -> Autres charges d'exploitation | C32: =$C$5*D32 -> 0 | D32: ='Charges dexploitation'!G31 -> 0 | E32: =D32*$E$5 -> 0
B34: Crédits Clients | C34: 120000 | D34: 100000 | E34: =D34*$E$5 -> 100000
B35: Dettes Fournisseurs | C35: 2500000 | D35: =C35*1.1 -> 2750000 | E35: =D35*$E$5 -> 2750000
B36: Total Besoins | C36: =SUM(C7:C34) -> 43907940 | D36: =SUM(D9:D34) -> 32056480 | E36: =SUM(E9:E34) -> 32056480
B37: Dotation trimestrielle ou semestrielle en Fonds de Roulement | C37: =C36-C35 -> 41407940 | D37: =D36-D35 -> 29306480 | E37: =D37*$E$5 -> 29306480

Sheet plan de finan initi
B2: PLAN DE FINANCEMENT INITIAL
C4: 1er jour
B5: BESOINS (durables)
B7: Frais d'établissement | C7: ='Coût du prjet'!C9 -> 114000
B9: Eléments incorporels | C9: ='Coût du prjet'!C10 -> 830000
B11: Equipements d'exploitation | C11: ='Coût du prjet'!C15 -> 892360
B13: Matériels et Mobiliers de bureaux | C13: ='Coût du prjet'!C16 -> 1110000
B15: Aménagements, Travaux et Installations | C15: ='Coût du prjet'!C17 -> 1110000
B17: Dépôts et cautionnement | C17: ='Coût du prjet'!C19 -> 182000
B19: ='Coût du prjet'!B20 -> Dotation trimestrielle ou semestrielle en Fonds de Roulement | C19: =+'Coût du prjet'!C20 -> 300000
B21: TOTAL DES BESOINS | C21: =SUM(C6:C20) -> 4538360
B24: RESSOURCES (durables)
B26: Fonds Propres | C26: =C27+C28+C29 -> 55000000
B27: Capital Social (apports des promoteurs) | C27: 25000000
B28: Comptes courants d'associés | C28: 20000000
B29: Aides et subventions | C29: 10000000
B32: Capitaux empruntés (emprunts à moyen et long terme)
B34: TOTAL DES RESSOURCES | C34: =C26+C32 -> 55000000
B37: ECART = Total Ressources - Total Besoins | C37: =C34-C21 -> 50461640

Sheet emprunt
C1: Conditions de l'emprunt : Banque
B3: Montant de l'emprunt | F3: ='plan de finan initi'!C32
B4: Système de remboursement | D4: Remboursement constant | F4: annuel ou mensuel
B5: si remboursement annuel | D5: taux d'intérêt nominal annuel | F5: 0.05
B6: si remboursement mensuel | D6: taux d'intérêt nominal mensuel | F6: =F5/12 -> 0.0041666667
D7: Taxe sur les Opérations Bancaires | F7: 0.07
B10: Périodes | C10: Dette debut de période | D10: Intérêt de la période | E10: TOB | F10: Amortissement de la période | G10: Annuité de la période | H10: Dette fin de période
B11: 1 | C11: 134 | D11: 500000 | E11: =D11*$F$7 -> 35000 | F11: =C11/36 -> 3.7222222 | G11: =SUM(D11:F11) -> 535003.72 | H11: =C11-F11 -> 130.27778
B12: 2 | C12: 34 | D12: 350000 | E12: =D12*$F$7 -> 24500 | F12: =C12/36 -> 0.94444444 | G12: =SUM(D12:F12) -> 374500.94 | H12: =C12-F12 -> 33.055556
B13: 3 | C13: 260 | D13: 200000 | E13: =D13*$F$7 -> 14000 | F13: =C13/36 -> 7.2222222 | G13: =SUM(D13:F13) -> 214007.22 | H13: =C13-F13 -> 252.77778
F15: =F14
B47: Somme | C47: =SUM(C11:C46) -> 428 | D47: =SUM(D11:D46) -> 1050000 | E47: =SUM(E11:E46) -> 73500 | F47: =SUM(F11:F46) -> 11.888889 | G47: =SUM(G11:G46) -> 1123511.9

Sheet estimation CA prévisionnels
C2: Chiffre d'affaires prévisionnels sur 3 ans : Cas d'activités saisonnières
D4: Quantités prévue par mois | E4: Prix Unitaire | F4: Chiffre d'Affaires Mensuel | G4: Chiffre d'Affaires de la période
C5: En saison :
C6: Ventes de porte clé | D6: 100 | E6: 2500 | F6: =PRODUCT(D6,E6) -> 250000 | G6: =PRODUCT(F6,9) -> 2250000
C7: Ventes de jeux | D7: 50 | E7: 10000 | F7: =PRODUCT(D7,E7) -> 500000 | G7: =PRODUCT(F7,9) -> 4500000
C8: Ventes de plateaux | D8: 50 | E8: 30000 | F8: =PRODUCT(D8,E8) -> 1500000 | G8: =PRODUCT(F8,9) -> 13500000
C9: Ventes de tableaux | D9: 50 | E9: 50000 | F9: =PRODUCT(D9,E9) -> 2500000 | G9: =PRODUCT(F9,9) -> 22500000
C10: Autres ventes | D10: 100 | E10: 50000 | F10: =PRODUCT(D10,E10) -> 5000000 | G10: =PRODUCT(F10,9) -> 45000000
C12: CA En saison | F12: =SUM(F6:F11) -> 9750000 | G12: =SUM(G6:G11) -> 87750000
C14: Transition:
C15: Ventes de porte clé | D15: 90 | E15: 2500 | F15: =PRODUCT(D15,E15) -> 225000 | G15: =PRODUCT(F15,1) -> 225000
C16: Ventes de jeux | D16: 40 | E16: 10000 | F16: =PRODUCT(D16,E16) -> 400000 | G16: =PRODUCT(F16,1) -> 400000
C17: Ventes de plateaux | D17: 40 | E17: 30000 | F17: =PRODUCT(D17,E17) -> 1200000 | G17: =PRODUCT(F17,1) -> 1200000
C18: Ventes de tableaux | D18: 40 | E18: 50000 | F18: =PRODUCT(D18,E18) -> 2000000 | G18: =PRODUCT(F18,1) -> 2000000
C19: Autres ventes | D19: 95 | E19: 50000 | F19: =PRODUCT(D19,E19) -> 4750000 | G19: =PRODUCT(F19,1) -> 4750000
C21: CA Transition | F21: =SUM(F15:F20) -> 8575000 | G21: =SUM(G15:G20) -> 8575000
C23: Hors saison:
C24: Ventes de porte clé | D24: 75 | E24: 2500 | F24: =PRODUCT(D24,E24) -> 187500 | G24: =PRODUCT(F24,2) -> 375000
C25: Ventes de jeux | D25: 20 | E25: 10000 | F25: =PRODUCT(D25,E25) -> 200000 | G25: =PRODUCT(F25,2) -> 400000
C26: Ventes de plateaux | D26: 30 | E26: 30000 | F26: =PRODUCT(D26,E26) -> 900000 | G26: =PRODUCT(F26,2) -> 1800000
C27: Ventes de tableaux | D27: 30 | E27: 50000 | F27: =PRODUCT(D27,E27) -> 1500000 | G27: =PRODUCT(F27,2) -> 3000000
C28: Autres ventes | D28: 70 | E28: 50000 | F28: =PRODUCT(D28,E28) -> 3500000 | G28: =PRODUCT(F28,2) -> 7000000
C30: CA Hors saison | F30: =SUM(F24:F28) -> 6287500 | G30: =SUM(G24:G28) -> 12575000
C32: C.A. hors taxe TOTAL DE LA 1ère ANNEE | G32: =SUM(G12,G21,G30) -> 108900000
C33: C.A. hors taxe TOTAL DE LA 2ème ANNEE | G33: =G32*(1+ 2%) -> 111078000
C34: C.A. hors taxe TOTAL DE LA 3ème ANNEE | G34: =G33*(1+ 3%) -> 114410340

Sheet compte dexploit
B4: COMPTE DE RESULTATS PREVISIONNELS SUR 3 ANS (avec soldes intermédiaires de gestion)
B6: Libellé (en F.CFA) | C6: 1ère Année | D6: 2ème Année | E6: 3ème Année
B7: Chiffre d'affaires hors taxe (SIG 1) | C7: ='estimation CA prévisionnels'!G32 -> 108900000 | D7: ='estimation CA prévisionnels'!G33 -> 111078000 | E7: ='estimation CA prévisionnels'!G34 -> 114410340
C8: 4.0% | D8: =(D7-C7)/C7 -> 0.02 | E8: =(E7-D7)/D7 -> 0.03
B9: Charges d'exploitation hors Frais Personnel & Dotations aux Amts et aux Prov
B10: Achats de marchandises | C10: ='Dotation en FR'!C7 -> 0 | D10: ='Dotation en FR'!D7 | E10: ='Dotation en FR'!E7 -> 0
B11: Achats de matières premières et fournitures liées | C11: ='Dotation en FR'!C8 -> 10707960 | D11: ='Dotation en FR'!D8 -> 10707960 | E11: ='Dotation en FR'!E8 -> 10707960
B12: Achats de consommables | C12: ='Dotation en FR'!C9 -> 0 | D12: ='Dotation en FR'!D9 -> 0 | E12: ='Dotation en FR'!E9 -> 0
B13: Achats de combustibles | C13: ='Dotation en FR'!C10 -> 0 | D13: ='Dotation en FR'!D10 -> 0 | E13: ='Dotation en FR'!E10 -> 0
B14: Achats de produits d'entretien | C14: ='Dotation en FR'!C11 -> 840000 | D14: ='Dotation en FR'!D11 -> 840000 | E14: ='Dotation en FR'!E11 -> 840000
B15: Achats de fournitures de bureau | C15: ='Dotation en FR'!C12 -> 13320000 | D15: ='Dotation en FR'!D12 -> 13320000 | E15: ='Dotation en FR'!E12 -> 13320000
B16: Eau (en terme de facture à payer) | C16: ='Dotation en FR'!C13 -> 24000 | D16: ='Dotation en FR'!D13 -> 24000 | E16: ='Dotation en FR'!E13 -> 24000
B17: Electricité (en terme de facture à payer) | C17: ='Dotation en FR'!C14 -> 240000 | D17: ='Dotation en FR'!D14 -> 240000 | E17: ='Dotation en FR'!E14 -> 240000
B18: Achats de petits matériels et outillages | C18: ='Dotation en FR'!C15 -> 0 | D18: ='Dotation en FR'!D15 -> 0 | E18: ='Dotation en FR'!E15 -> 0
B19: Etudes et prestations de service | C19: ='Dotation en FR'!C16 -> 0 | D19: ='Dotation en FR'!D16 -> 0 | E19: ='Dotation en FR'!E16 -> 0
B20: Achats d'emballages | C20: ='Dotation en FR'!C17 -> 600000 | D20: ='Dotation en FR'!D17 -> 600000 | E20: ='Dotation en FR'!E17 -> 600000
B21: Frais de transport | C21: ='Dotation en FR'!C18 -> 1200000 | D21: ='Dotation en FR'!D18 -> 1200000 | E21: ='Dotation en FR'!E18 -> 1200000
... B31: Charges provisionnées d'exploitation | C31: ='Dotation en FR'!C28 -> 0 | D31: ='Dotation en FR'!D28 -> 0 | E31: ='Dotation en FR'!E28 -> 0
B32: Autres charges d'exploitation | C32: ='Dotation en FR'!C32 -> 0 | D32: ='Dotation en FR'!D32 -> 0 | E32: ='Dotation en FR'!E32 -> 0
B33: Total charges d'expl Hors FP & DAP (1) | C33: =+SUM(C11:C27) -> 35571960 | D33: =+SUM(D11:D27) -> 35571960 | E33: =+SUM(E11:E27) -> 35571960
B34: Valeur Ajoutée (SIG 2) | C34: =C7-C33 -> 73328040 | D34: =D7-D33 -> 75506040 | E34: =E7-E33 -> 78838380
B35: Valeur Ajoutée / CA hors taxe*100 | C35: =C34/C7 -> 0.67335207 | D35: =D34/D7 -> 0.67975693 | E35: =E34/E7 -> 0.6890844
B36: Charges de personnel | C36: ='Dotation en FR'!C29+'Dotation en FR'!C30 -> 4512480 | D36: ='Dotation en FR'!D29+'Dotation en FR'!D30 -> 4512480 | E36: ='Dotation en FR'!E29+'Dotation en FR'!E30 -> 4512480
B37: Excédent brut d'exploitation (SIG 3) | C37: =+C34-C36 -> 68815560 | D37: =+D34-D36 -> 70993560 | E37: =+E34-E36 -> 74325900
B38: EBE/ CA hors taxe*100 | C38: =C37/C7 -> 0.63191515 | D38: =D37/D7 -> 0.6391325 | E38: =E37/E7 -> 0.64964321
B39: Dotation aux amortissements et aux provisions | C39: =amortis!D24 -> 1479330 | D39: =amortis!F24 -> 1479330 | E39: =amortis!H24 -> 1479330
B40: Résultat d'exploitation (SIG 4) | C40: =+C37-C39 -> 67336230 | D40: =+D37-D39 -> 69514230 | E40: =+E37-E39 -> 72846570
B41: RE/CA hors taxe*100 | C41: =C40/C7 -> 0.61833085 | D41: =D40/D7 -> 0.62581456 | E41: =E40/E7 -> 0.63671317
B42: Activités Financières
B43: Revenus financiers
B44: Gains de change
B45: Total produits financiers | C45: =SUM(C43:C44) -> 0 | D45: =SUM(D43:D44) -> 0 | E45: =SUM(E43:E44) -> 0
B46: Frais financiers (intérêts bancaires) | C46: ='Charges dexploitation'!G30 -> 1050000 | D46: ='Dotation en FR'!D31 -> 0 | E46: ='Dotation en FR'!E31 -> 0
B47: Pertes de change
B48: Total charges financières | C48: =SUM(C46:C47) -> 1050000 | D48: =SUM(D46:D47) -> 0 | E48: =SUM(E46:E47) -> 0
B49: Résultat financier (SIG 5) | C49: =C45-C48 -> -1050000 | D49: =D45-D48 -> 0 | E49: =E45-E48 -> 0
B51: Résultat des activités ordinaires (SIG 6) | C51: =+C40+C49 -> 66286230 | D51: =+D40+D49 -> 69514230 | E51: =+E40+E49 -> 72846570
B52: Impôts sur le résultat (25%) | C52: =C51*25% -> 16571558 | D52: =D51*25% -> 17378558 | E52: =E51*25% -> 18211642
B53: Résultat net (SIG 7) | C53: =C51-C52 -> 49714672 | D53: =D51-D52 -> 52135672 | E53: =E51-E52 -> 54634928
B54: Dividendes (20%) | C54: =C53*20% -> 9942934.5 | D54: =D53*20% -> 10427134 | E54: =E53*20% -> 10926986
...

Sheet Rentabilité 1
B4: RENTABILITE DES CAPITAUX= RN/Capitaux propres (dans le plan de financement) | C4: ='compte dexploit'!C53/55000000 -> 0.90390314 | D4: ='compte dexploit'!D53/55000000 -> 0.94792132 | E4: ='compte dexploit'!E53/55000000 -> 0.99336232
B5: Autofinancement Net (Solde Financier 1) | C5: ='compte dexploit'!C55+'compte dexploit'!C39 -> 41251068 | D5: ='compte dexploit'!D55+'compte dexploit'!D39 -> 43187868 | E5: ='compte dexploit'!E55+'compte dexploit'!E39 -> 45187272
B6: ACTUALISATION ((1+i)PUISSANCE(-n)) | C6: =POWER((1+0),(-1)) -> 1 | D6: =POWER((1+12),(-1)) -> 0.076923077 | E6: =POWER((1+12),(-1)) -> 0.076923077
B7: Autofinancement Net Actualisé | C7: =C5*C6 -> 41251068 | D7: =D5*D6 -> 3322143.7 | E7: =E5*E6 -> 3475944
B8: Cumul des Autofinancements Nets | C8: =C7 -> 41251068 | D8: =C8+D7 -> 44573212 | E8: =D8+E7 -> 48049156
B12: VAN (i%) | C12: =E8-'Coût du prjet'!C22 -> 36402436
B14: Les 12% sont à titre indicatif. Il faut travailler avec les vrais chiffres vérifiés auprès de vos banquiers. Les informations sur les actualisations se trouvent dans une table financière dans le tableau de l'actualisation à intérêts composés.
B16: CALCUL DU TAUX DE RENTABILITE INTERNE
B18: =B5 -> Autofinancement Net (Solde Financier 1) | C18: =C5 -> 41251068 | D18: =D5 -> 43187868 | E18: =E5 -> 45187272
B19: ACTUALISATION (i = X%) ou (1+X%)PUISSANCE(-n) | C19: =POWER(1+12%,"-1") -> 0.89285714 | D19: =POWER(1+12%,"-1") -> 0.89285714 | E19: =POWER(1+12%,"-1") -> 0.89285714
B20: =B7 -> Autofinancement Net Actualisé | C20: =C18*C19 -> 36831311 | D20: =D18*D19 -> 38560596 | E20: =E18*E19 -> 40345779
B21: =B8 -> Cumul des Autofinancements Nets | C21: =C20 -> 36831311 | D21: =C21+D20 -> 75391907 | E21: =D21+E20 -> 1.1573769e+08
B25: VAN (i%) | C25: =C12 -> 36402436
B27: VAN (TRI) | C27: 0
B29: VAN (X%) | C29: =E21-'Coût du prjet'!C22 -> 1.0409097e+08
B39: TRI | C39: =18+(22-18)*((0-C25)/(C29-C25)) -> 15.848827
B41: IP (12%) | C41: =(C25/'Coût du prjet'!C22)+1 -> 4.1255526

Sheet Rentabilité 2
B2: CALCUL DU SEUIL DE RENTABILITE
B4: Eléments | C4: 1ère année | D4: 2ème année | E4: 3ème année
B6: CHIFFRE D'AFFAIRES | C6: ='compte dexploit'!C7 -> 108900000 | D6: ='compte dexploit'!D7 -> 111078000 | E6: ='compte dexploit'!E7 -> 114410340
B8: CHARGES VARIABLES
B10: Achats de marchandises
B11: Achats de matières premières et fournitures liées
B12: Achats de consommables
B13: Achats de combustibles
B14: Achats de produits d'entretien
B15: Achats de fournitures de bureau | C15: 1110000
B16: Eau (en terme de facture à payer) | C16: 2000
B17: Electricité (en terme de facture à payer) | C17: 20000
B18: Achats de petits matériels et outillages
B19: Etudes et prestations de service
B20: Achats d'emballages | C20: 50000
B21: Frais de transport | C21: 100000
B22: Sous-traitance | C22: 60000
B24: TOTAL CHARGES VARIABLES | C24: =SUM(C10:C22) -> 1342000 | D24: =SUM(D10:D22) -> 0 | E24: =SUM(E10:E22) -> 0
B26: MARGE SUR COÛT VARIABLES | C26: =C6-C24 -> 107558000 | D26: =D6-D24 -> 111078000 | E26: =E6-E24 -> 114410340
B28: CHARGES FIXES
B29: Loyer | C29: 50000
B30: Charges sociales
B31: Allocations
B32: Internet | C32: 15000
B33: Frais de formation en Web master
B34: Impôt (Patente) | C34: 200000
B35: Frais financiers
B36: Assurance | C36: 150000
B37: Frais de publicité | C37: 300000 | D37: - | E37: -
B39: TOTAL CHARGES FIXES | C39: =SUM(C29:C37) -> 715000 | D39: =SUM(D29:D37) -> 0 | E39: =SUM(E29:E37) -> 0
B41: RESULTAT D'EXPLOITATION | C41: =C26-C39 -> 106843000 | D41: =D26-D39 -> 111078000 | E41: =E26-E39 -> 114410340
B43: SEUIL DE RENTABILITE | C43: =(C6*C39)/C26 -> 723921.05 | D43: =(D6*D39)/D26 -> 0 | E43: =(E6*E39)/E26 -> 0
B44: POINT MORT | C44: =C43*360/C6 -> 2.3931274 | D44: =(D43*360)/D6 -> 0 | E44: =(E43*360)/E6 -> 0

Sheet plan de trésorerie
C5: 1er mois | D5: 2è mois | E5: 3è mois | F5: 4è mois | G5: 5è mois | H5: 6è mois | I5: 7e mois | J5: 8e mois | K5: 9e mois | L5: 10e mois | M5: 11e mois | N5: 12e mois
B7: 1. SOLDE EN DEBUT DE MOIS | C7: ='plan de finan initi'!C37 -> 50461640 | D7: =C56 -> 49705596 | E7: =D56 -> 49508555 | F7: =E56 -> 49547508 | G7: =F56 -> 49822468 | H7: =G56 -> 50097428 | I7: =H56 -> 50372388 | J7: =I56 -> 51355348 | K7: =J56 -> 55524308 | ... N7: =M56 -> 68061188
B9: 2. ENCAISSEMENTS TTC
B10: 2A. Récettes d'exploitation | C10: =C13 -> 295000 | D10: =D13 -> 354000 | E10: =E13 -> 590000 | F10: =F13 -> 826000 | G10: =G13 -> 826000 | H10: =H13 -> 826000 | I10: =I13 -> 1534000 | J10: =J13 -> 4720000 | ... N10: =N13 -> 7434000
B11: Chiffre d'affaires encaissé | C11: 250000 | D11: 300000 | E11: 500000 | F11: 700000 | G11: 700000 | H11: 700000 | I11: 1300000 | J11: 4000000 | K11: 4000000 | L11: 4000000 | M11: 4000000 | N11: 6300000
B12: T V A Collectée sur les ventes (18%) | C12: =C11*18% -> 45000 | D12: =D11*18% -> 54000 | E12: =E11*18% -> 90000 | F12: =F11*18% -> 126000 | G12: =G11*18% -> 126000 | H12: =H11*18% -> 126000 | I12: =I11*18% -> 234000 | J12: =J11*18% -> 720000 | ... N12: =N11*18% -> 1134000
B13: Chiffre d'affaires encaissé TTC | C13: =SUM(C11:C12) -> 295000 | D13: =SUM(D11:D12) -> 354000 | E13: =SUM(E11:E12) -> 590000 | F13: =SUM(F11:F12) -> 826000 | G13: =SUM(G11:G12) -> 826000 | H13: =SUM(H11:H12) -> 826000 | I13: =SUM(I11:I12) -> 1534000 | J13: =SUM(J11:J12) -> 4720000 | ... N13: =SUM(N11:N12) -> 7434000
B14: 2B. Récettes Hors exploitation | C14: =C15+C16+C17 -> 0 | D14: =D15+D16+D17 -> 0 | E14: =E15+E16+E17 -> 0 | F14: =F15+F16+F17 -> 0 | G14: =G15+G16+G17 -> 0 | H14: =H15+H16+H17 -> 0 | I14: =I15+I16+I17 -> 0 | J14: =J15+J16+J17 -> 0 | ... N14: =N15+N16+N17 -> 0
B15: Apport en capital
B16: Apports en comptes courants d'associés
B17: Emprunts à moyen et long terme
B18: ……….
B19: A. TOTAL ENCAISSEMENTS = 2A + 2B | C19: =C10+C14 -> 295000 | D19: =D10+D14 -> 354000 | E19: =E10+E14 -> 590000 | F19: =F10+F14 -> 826000 | G19: =G10+G14 -> 826000 | H19: =H10+H14 -> 826000 | I19: =I10+I14 -> 1534000 | J19: =J10+J14 -> 4720000 | ... N19: =N10+N14 -> 7434000
B20: 3. DECAISSEMENTS TTC
B21: 3A. Dépenses d'exploitation TTC | C21: =C22+C23+C37+C38+C39+C40+C41+C42+C43+C44+C45+C46+C47+C48+C49 -> 1051040 | D21: =D22+D23+D37+D38+D39+D40+D41+D42+D43+D44+D45+D46+D47+D48+D49 -> 551040 | E21: =E22+E23+E37+E38+E39+E40+E41+E42+E43+E44+E45+E46+E47+E48+E49 -> 551040 | F21: =F22+F23+F37+F38+F39+F40+F41+F42+F43+F44+F45+F46+F47+F48+F49 -> 551040 | G21: =G22+G23+G37+G38+G39+G40+G41+G42+G43+G44+G45+G46+G47+G48+G49 -> 551040 | H21: =H22+H23+H37+H38+H39+H40+H41+H42+H43+H44+H45+H46+H47+H48+H49 -> 551040 | I21: =I22+I23+I37+I38+I39+I40+I41+I42+I43+I44+I45+I46+I47+I48+I49 -> 551040 | J21: =J22+J23+J37+J38+J39+J40+J41+J42+J43+J44+J45+J46+J47+J48+J49 -> 551040 | ... N21: =N22+N23+N37+N38+N39+N40+N41+N42+N43+N44+N45+N46+N47+N48+N49 -> 541040
B22: Achats de marchandises | C22: 0
B23: Achats de matières premières et fournitures liées | C23: 0
B24: Achats de consommables
B25: Achats de combustibles
B26: Achats de produits d'entretien
B27: Achats de fournitures de bureau
B28: Eau (en terme de facture à payer) | C28: 2000 | D28: 2000 | E28: 2000 | F28: 2000 | G28: 2000 | H28: 2000 | I28: 2000 | J28: 2000 | K28: 2000 | L28: 2000 | M28: 2000 | N28: 2000
B29: Electricité (en terme de facture à payer) | C29: 20000 | D29: 20000 | E29: 20000 | F29: 20000 | G29: 20000 | H29: 20000 | I29: 20000 | J29: 20000 | K29: 20000 | L29: 20000 | M29: 20000 | N29: 20000
B30: Achats de petits matériels et outillages
B31: Etudes et prestations de service
B32: Achats d'emballages | C32: 50000 | J32: 50000
B33: Frais de transport | C33: 100000 | H33: 100000
B34: Sous-traitance | C34: 60000 | D34: 60000 | E34: 60000 | F34: 60000 | G34: 60000 | H34: 60000 | I34: 60000 | J34: 60000 | K34: 60000 | L34: 60000 | M34: 60000 | N34: 60000
B35: Loyer | C35: ='Charges dexploitation'!D19 -> 50000 | D35: =C35 -> 50000 | E35: =C35 -> 50000 | F35: =E35 -> 50000 | G35: =F35 -> 50000 | H35: =F35 -> 50000 | I35: =H35 -> 50000 | J35: =H35 -> 50000 | K35: =I35 -> 50000 | L35: =K35 -> 50000 | M35: =K35 -> 50000 | N35: =L35 -> 50000
B36: Entretien, Réparations et Maintenance | C36: 150000
B37: Primes d'assurance | C37: 150000 | D37: 150000 | E37: 150000 | F37: 150000 | G37: 150000 | H37: 150000 | I37: 150000 | J37: 150000 | K37: 150000 | L37: 150000 | M37: 150000 | N37: 150000
B38: Publicité | C38: 300000
B39: Téléphone (en terme de facture à payer) | C39: 10000 | D39: 10000 | E39: 10000 | F39: 10000 | G39: 10000 | H39: 10000 | I39: 10000 | J39: 10000
B40: Internet (en terme de facture à payer) | C40: 15000 | D40: 15000 | E40: 15000 | F40: 15000 | G40: 15000 | H40: 15000 | I40: 15000 | J40: 15000 | K40: 15000 | L40: 15000 | M40: 15000 | N40: 15000
B41: Commissions et frais assimilés | C41: 0
B42: Impôts (Patente et autres droits) | C42: 200000
B43: Charges provisionnées | C43: 0
B44: Salaires bruts et autres rémunérations | C44: 340000 | D44: 340000 | E44: 340000 | F44: 340000 | G44: 340000 | H44: 340000 | I44: 340000 | J44: 340000 | K44: 340000 | L44: 340000 | M44: 340000 | N44: 340000
B45: Charges sociales | C45: 36040 | D45: 36040 | E45: 36040 | F45: 36040 | G45: 36040 | H45: 36040 | I45: 36040 | J45: 36040 | K45: 36040 | L45: 36040 | M45: 36040 | N45: 36040
B46: Frais financiers | C46: 0
...

Sheet TERE
B2: TABLEAU D'EQUILIBRE RESSOURCES/EMPLOIS DE FONDS
B4: Rubriques | C4: Année 0 | D4: Année 1 | E4: Année 2 | F4: Année 3
B5: Coefficient d'inflation | D5: 1 | E5: 1 | F5: 1
B7: Ressources
B8: Autofinancements nets | C8: 0 | D8: ='Rentabilité 1'!C5 -> 41251068 | E8: ='Rentabilité 1'!D5 -> 43187868 | F8: ='Rentabilité 1'!E5 -> 45187272
B9: Capitaux propres | C9: ='plan de finan initi'!C26 -> 55000000 | D9: ='plan de finan initi'!D23 | E9: ='plan de finan initi'!E23 | F9: ='plan de finan initi'!F23
B10: Capitaux empruntés | C10: ='plan de finan initi'!C32
B11: Reprises FDR
B12: Valeurs résiduelles
B13: Sous Total Ressources | C13: =SUM(C8:C12) -> 55000000 | D13: =SUM(D8:D12) -> 41251068 | E13: =SUM(E8:E12) -> 43187868 | F13: =SUM(F8:F12) -> 45187272
B15: Emplois
B16: Investissements et Renouvellements | C16: ='plan de finan initi'!C7+'plan de finan initi'!C9+'plan de finan initi'!C11+'plan de finan initi'!C13+'plan de finan initi'!C15+'plan de finan initi'!C17 -> 4238360 | D16: 0 | E16: 0 | F16: 0
B17: Remboursement principal | D17: =SUM(emprunt!F11:F22) -> 11.888889 | E17: =SUM(emprunt!F23:F34) -> 0 | F17: =SUM(emprunt!F35:F46) -> 0
B18: Dotation en FDR | C18: ='Dotation en FR'!C37 -> 41407940 | D18: 0 | E18: 0
B19: Distribution Dividendes | D19: ='compte dexploit'!C54 -> 9942934.5 | E19: ='compte dexploit'!D54 -> 10427134 | F19: ='compte dexploit'!E54 -> 10926986
B20: Sous Total Emplois | C20: =SUM(C16:C19) -> 45646300 | D20: =SUM(D16:D19) -> 9942946.4 | E20: =SUM(E16:E19) -> 10427134 | F20: =SUM(F16:F19) -> 10926986
B22: Solde Annuel Ressources/Emplois | C22: =C13-C20 -> 9353700 | D22: =D13-D20 -> 31308122 | E22: =E13-E20 -> 32760734 | F22: =F13-F20 -> 34260286
B23: Trésorerie Début d'année | C23: =0 -> 0 | D23: =C24 -> 9353700 | E23: =D24 -> 40661822 | F23: =E24 -> 73422555
B24: Trésorerie Fin d'année | C24: =C22+C23 -> 9353700 | D24: =SUM(D22:D23) -> 40661822 | E24: =SUM(E22:E23) -> 73422555 | F24: =SUM(F22:F23) -> 1.0768284e+08
